<?xml version="1.0" ?>
<!-- =================================================================================== -->
<!-- |    This document was autogenerated by xacro from urdf/jy_arm.xacro              | -->
<!-- |    EDITING THIS FILE BY HAND IS NOT RECOMMENDED                                 | -->
<!-- =================================================================================== -->
<robot xmlns:xacro="http://www.ros.org/wiki/xacro" name="jy_arm">
  <link name="base_link">
    <inertial>
      <origin xyz="-0.00011106458799925955 0.06311159153372557 0.013057877386527852" rpy="0 0 0"/>
      <mass value="5.366253574558696"/>
      <inertia ixx="0.011666" iyy="0.009197" izz="0.013373" ixy="-0.0" iyz="-0.000402" ixz="-0.0"/>
    </inertial>
    <visual>
      <origin xyz="0 0 0" rpy="0 0 0"/>
      <geometry>
        <mesh filename="package://jy_arm_description/meshes/base_link.stl" scale="0.001 0.001 0.001"/>
      </geometry>
      <material name="silver"/>
    </visual>
    <collision>
      <origin xyz="0 0 0" rpy="0 0 0"/>
      <geometry>
        <mesh filename="package://jy_arm_description/meshes/base_link.stl" scale="0.001 0.001 0.001"/>
      </geometry>
    </collision>
  </link>
  <link name="elbow_1">
    <inertial>
      <origin xyz="-0.018598185056512773 0.042969594521089005 0.021525519944900307" rpy="0 0 0"/>
      <mass value="0.47914913697859285"/>
      <inertia ixx="0.000369" iyy="0.000171" izz="0.000397" ixy="8.8e-05" iyz="-4.1e-05" ixz="2.7e-05"/>
    </inertial>
    <visual>
      <origin xyz="-0.024539 -0.301316 0.022486" rpy="0 0 0"/>
      <geometry>
        <mesh filename="package://jy_arm_description/meshes/elbow_1.stl" scale="0.001 0.001 0.001"/>
      </geometry>
      <material name="silver"/>
    </visual>
    <collision>
      <origin xyz="-0.024539 -0.301316 0.022486" rpy="0 0 0"/>
      <geometry>
        <mesh filename="package://jy_arm_description/meshes/elbow_1.stl" scale="0.001 0.001 0.001"/>
      </geometry>
    </collision>
  </link>
  <link name="forearm_1">
    <inertial>
      <origin xyz="-0.009704250720106458 0.0004656574510826794 -0.06766874466878209" rpy="0 0 0"/>
      <mass value="0.5145873026308719"/>
      <inertia ixx="0.000846" iyy="0.000886" izz="0.000112" ixy="2e-06" iyz="1e-06" ixz="-1.6e-05"/>
    </inertial>
    <visual>
      <origin xyz="0.000111 -0.3533 0.012492" rpy="0 0 0"/>
      <geometry>
        <mesh filename="package://jy_arm_description/meshes/forearm_1.stl" scale="0.001 0.001 0.001"/>
      </geometry>
      <material name="silver"/>
    </visual>
    <collision>
      <origin xyz="0.000111 -0.3533 0.012492" rpy="0 0 0"/>
      <geometry>
        <mesh filename="package://jy_arm_description/meshes/forearm_1.stl" scale="0.001 0.001 0.001"/>
      </geometry>
    </collision>
  </link>
  <link name="hand_1">
    <inertial>
      <origin xyz="0.00021385622241918795 8.54127877321087e-05 -0.008045775876672184" rpy="0 0 0"/>
      <mass value="0.0009288640955598442"/>
      <inertia ixx="0.0" iyy="0.0" izz="0.0" ixy="-0.0" iyz="0.0" ixz="0.0"/>
    </inertial>
    <visual>
      <origin xyz="0.000111 -0.3533 0.207992" rpy="0 0 0"/>
      <geometry>
        <mesh filename="package://jy_arm_description/meshes/hand_1.stl" scale="0.001 0.001 0.001"/>
      </geometry>
      <material name="silver"/>
    </visual>
    <collision>
      <origin xyz="0.000111 -0.3533 0.207992" rpy="0 0 0"/>
      <geometry>
        <mesh filename="package://jy_arm_description/meshes/hand_1.stl" scale="0.001 0.001 0.001"/>
      </geometry>
    </collision>
  </link>
  <link name="base_rotor_1">
    <inertial>
      <origin xyz="-0.006646332363299095 0.01292667635559297 -0.005624744916669085" rpy="0 0 0"/>
      <mass value="0.39974448473287827"/>
      <inertia ixx="0.000167" iyy="0.00025" izz="0.000145" ixy="2.8e-05" iyz="3.7e-05" ixz="-6.2e-05"/>
    </inertial>
    <visual>
      <origin xyz="0.000111 -0.1273 -0.012508" rpy="0 0 0"/>
      <geometry>
        <mesh filename="package://jy_arm_description/meshes/base_rotor_1.stl" scale="0.001 0.001 0.001"/>
      </geometry>
      <material name="silver"/>
    </visual>
    <collision>
      <origin xyz="0.000111 -0.1273 -0.012508" rpy="0 0 0"/>
      <geometry>
        <mesh filename="package://jy_arm_description/meshes/base_rotor_1.stl" scale="0.001 0.001 0.001"/>
      </geometry>
    </collision>
  </link>
  <link name="arm_1">
    <inertial>
      <origin xyz="0.021930134761569527 0.07282616378941456 -0.0017490427054493891" rpy="0 0 0"/>
      <mass value="3.0392859375785495"/>
      <inertia ixx="0.009853" iyy="0.001355" izz="0.010273" ixy="0.000887" iyz="-5.6e-05" ixz="9e-06"/>
    </inertial>
    <visual>
      <origin xyz="0.018611 -0.155316 0.022486" rpy="0 0 0"/>
      <geometry>
        <mesh filename="package://jy_arm_description/meshes/arm_1.stl" scale="0.001 0.001 0.001"/>
      </geometry>
      <material name="silver"/>
    </visual>
    <collision>
      <origin xyz="0.018611 -0.155316 0.022486" rpy="0 0 0"/>
      <geometry>
        <mesh filename="package://jy_arm_description/meshes/arm_1.stl" scale="0.001 0.001 0.001"/>
      </geometry>
    </collision>
  </link>
  <link name="wrist_1">
    <inertial>
      <origin xyz="-0.005171387015090242 -0.0025269947515656477 -0.0467670980512126" rpy="0 0 0"/>
      <mass value="0.18202125492055582"/>
      <inertia ixx="9.5e-05" iyy="9.5e-05" izz="2.2e-05" ixy="0.0" iyz="-1e-06" ixz="-1.4e-05"/>
    </inertial>
    <visual>
      <origin xyz="-0.009689 -0.3533 0.137492" rpy="0 0 0"/>
      <geometry>
        <mesh filename="package://jy_arm_description/meshes/wrist_1.stl" scale="0.001 0.001 0.001"/>
      </geometry>
      <material name="silver"/>
    </visual>
    <collision>
      <origin xyz="-0.009689 -0.3533 0.137492" rpy="0 0 0"/>
      <geometry>
        <mesh filename="package://jy_arm_description/meshes/wrist_1.stl" scale="0.001 0.001 0.001"/>
      </geometry>
    </collision>
  </link>
  <joint name="arm_to_elbow" type="continuous">
    <origin xyz="0.04315 0.146 0.0" rpy="0 0 0"/>
    <parent link="arm_1"/>
    <child link="elbow_1"/>
    <axis xyz="1.0 0.0 -0.0"/>
  </joint>
  <joint name="elbow_to_forearm" type="continuous">
    <origin xyz="-0.02465 0.051984 0.009994" rpy="0 0 0"/>
    <parent link="elbow_1"/>
    <child link="forearm_1"/>
    <axis xyz="-0.0 -0.0 -1.0"/>
  </joint>
  <joint name="wrist_to_arm" type="continuous">
    <origin xyz="-0.0098 0.0 -0.0705" rpy="0 0 0"/>
    <parent link="wrist_1"/>
    <child link="hand_1"/>
    <axis xyz="0.0 0.0 -1.0"/>
  </joint>
  <joint name="base_link_to_base_rotor" type="continuous">
    <origin xyz="-0.000111 0.1273 0.012508" rpy="0 0 0"/>
    <parent link="base_link"/>
    <child link="base_rotor_1"/>
    <axis xyz="-0.0 1.0 0.0"/>
  </joint>
  <joint name="base_rotor_to_arm" type="continuous">
    <origin xyz="-0.0185 0.028016 -0.034994" rpy="0 0 0"/>
    <parent link="base_rotor_1"/>
    <child link="arm_1"/>
    <axis xyz="1.0 0.0 -0.0"/>
  </joint>
  <joint name="forearm_to_wrist" type="continuous">
    <origin xyz="0.0098 0.0 -0.125" rpy="0 0 0"/>
    <parent link="forearm_1"/>
    <child link="wrist_1"/>
    <axis xyz="1.0 -0.0 -0.0"/>
  </joint>
</robot>
